<?xml version="1.0"?>
<robot xmlns:xacro="http://www.ros.org/wiki/xacro" name="myfirst">

  <link name="base_link">
    <visual>
      <geometry>
        <box size="0.37 0.37 0.04"/>
      </geometry>
    </visual>

    <collision>
      <geometry>
        <box size="0.37 0.37 0.04"/>
      </geometry>
    </collision>

    <inertial>
      <mass value=".2" />
      <inertia ixx="0.00231" ixy="0.0" ixz="0.0" iyy=".00231" iyz="0.0" izz="0.00456" />
    </inertial>
  </link>
    
  <link name="right_wheel">
    <visual>
      <geometry>
        <cylinder length="0.05" radius="0.08"/>
      </geometry>
    </visual>

    <collision>
      <geometry>
        <cylinder radius="0.08" length="0.05" />
      </geometry>
    </collision>

    <inertial>
      <mass value="0.1"/>
      <inertia ixx="0.00018" ixy="0" ixz="0" iyy="0.00018" iyz="0" izz="0.00032" />
    </inertial>
  </link>

  <joint name="base_to_right_wheel" type="continuous">
    <origin xyz="0.0925 0 0" rpy="0 ${-pi/2} 0"/>
    <parent link="base_link"/>
    <child link="right_wheel"/>
    <axis xyz = "0 0 1"/>
  </joint>

  <link name="left_wheel">
    <visual>
      <geometry>
        <cylinder length="0.05" radius="0.08"/>
      </geometry>
    </visual>

    <collision>
      <geometry>
        <cylinder radius="0.08" length="0.05" />
      </geometry>
    </collision>

    <inertial>
      <mass value=".1"/>
      <inertia ixx="0.00018" ixy="0" ixz="0" iyy="0.00018" iyz="0" izz="0.00032" />
    </inertial>
  </link>

  <joint name="base_to_left_wheel" type="continuous">
    <origin xyz="-0.0925 0 0" rpy="0 ${-pi/2} 0"/>
    <parent link="base_link"/>
    <child link="left_wheel"/>
    <axis xyz = "0 0 1"/>
  </joint>

  <link name="front_castor">
    <visual>
      <geometry>
        <sphere radius= "0.04"/>
      </geometry>
    </visual>

    <collision>
      <geometry>
        <sphere radius="0.04" />
      </geometry>
    </collision>

    <inertial>
      <mass value=".05" />
      <inertia ixx="0.00032" ixy="0.0" ixz="0.0" iyy="0.00032" iyz="0.0" izz="0.00032" />
    </inertial>

  </link>

  <joint name="base_to_front_castor" type="fixed">
    <origin xyz="0 0.12 -.04" rpy="0 1.57 0"/>
    <parent link="base_link"/>
    <child link="front_castor"/>
  </joint>

  <link name="back_castor">
    
    <visual>
      <geometry>
        <sphere radius= "0.04"/>
      </geometry>
    </visual>

    <collision>
      <geometry>
        <sphere radius="0.04" />
      </geometry>
    </collision>

    <inertial>
      <mass value=".05" />
      <inertia ixx="0.00032" ixy="0.0" ixz="0.0" iyy="0.00032" iyz="0.0" izz="0.00032" />
    </inertial>

  </link>

  <joint name="base_to_back_castor" type="fixed">
    <origin xyz="0 -0.12 -.04" rpy="0 1.57 0"/>
    <parent link="base_link"/>
    <child link="back_castor"/>
  </joint> 
  <joint name="footprint_joint" type="fixed">
    <parent link="base_link"/>
    <child link="base_footprint"/>
    <origin xyz="0 0 -0.08"/>
  </joint>

  <link name="base_footprint">
  </link>


  <gazebo>
    <plugin name="differential_drive_controller" filename="libgazebo_ros_diff_drive.so">        
        <!-- wheels -->
        <left_joint>base_to_left_wheel</left_joint>
        <right_joint>base_to_right_wheel</right_joint>

        <!-- kinematics -->
        <wheel_separation>0.185</wheel_separation>
        <wheel_diameter>0.16</wheel_diameter>

        <!-- tfs -->
        <publish_odom>true</publish_odom>
        <publish_odom_tf>true</publish_odom_tf>
        <publish_wheel_tf>true</publish_wheel_tf>
        <odometry_frame>odom</odometry_frame>

        <!-- limits -->
        <max_wheel_torque>20</max_wheel_torque>
        <max_acceleration>1.0</max_acceleration>

        <!-- miscs -->
        <robot_base_frame>base_link</robot_base_frame>
        <update_rate>50</update_rate>
    </plugin>
  </gazebo>

  <gazebo reference="back_castor">
    <mu1>0</mu1>
    <mu2>0</mu2>
    <material>Gazebo/Red</material>
  </gazebo>

  <gazebo reference="back_castor">
    <mu1>0</mu1>
    <mu2>0</mu2>
    <material>Gazebo/Red</material>
  </gazebo>



  <!-- LIDAR -->
  <joint name = "lidar_joint" type = "fixed">
    <parent link = "base_link"/>
    <child link = "lidar_link"/>
    <origin xyz = "0 0 0.1"/>
  </joint>

  <link name = "lidar_link">
    <visual>
      <geometry>
        <cylinder radius = "0.05" length = "0.02"/>
      </geometry>
    </visual>

    <collision>
      <geometry>
        <cylinder radius = "0.05" length = "0.02"/>
      </geometry>
    </collision>

    <inertial>
      <mass value=".1" />
      <inertia ixx="${(.1/12) * (3*.01*.01 + .01*.01)}" ixy="0" ixz="0" iyy="${(.1/12) * (3*.01*.01 + .01*.01)}" iyz="0" izz="${(.1/2) * (.01*.01)}" />
    </inertial>
  </link>



<gazebo reference="lidar_link">
    <material>Gazebo/Black</material>
    <sensor name="lidar" type="ray">
        <always_on>true</always_on>
        <visualize>true</visualize>
        <update_rate>5</update_rate>
        <ray>
            <scan>
                <horizontal>
                    <samples>360</samples>
                    <resolution>1.000000</resolution>
                    <min_angle>0.000000</min_angle>
                    <max_angle>6.280000</max_angle>
                </horizontal>
            </scan>
            <range>
                <min>0.120000</min>
                <max>6</max>
                <resolution>0.015000</resolution>
            </range>
            <noise>
                <type>gaussian</type>
                <mean>0.0</mean>
                <stddev>0.01</stddev>
            </noise>
        </ray>
        <plugin name="scan" filename="libgazebo_ros_ray_sensor.so">
            <ros>
                <remapping>~/out:=scan</remapping>
            </ros>
            <output_type>sensor_msgs/LaserScan</output_type>
            <!-- <frame_name>lidar_link</frame_name> -->
        </plugin>
    </sensor>
</gazebo>

  
</robot> 